Workbook
Name Длязакупа: 'Для закупа'!$B$1:$C$94
Name Длязакупа: 'Расчет с_стоим'!$B$2:$C$74

Sheet Технология
B1: вес торта, без крема | E1: общий вес готового торта | I1: =B2/L1 -> 1.000435 | J1: Если ярусный то указать | K1: 1 | L1: =((('1'!F2+'2'!F2+'3'!F2+'4'!F2+'5'!F2+'6'!F2))) -> 2299 | M1: Первый расчет на форму диаметром | R1: 22 | S1: =IFERROR((R2*L2),"")/K1*0.47 -> 10.348997 | T1: 1 ярус | V1: Белок на БЗК гр | W1: =U4*B2 -> 81.777778
B2: 2300 | F2: ='Расчет с_стоим'!C3 -> 2589.1172 | L2: =B2/L1 -> 1.000435 | M2: В пересчете на форму диаметром | R2: =IFERROR((R1*L2),"") -> 22.009569 | S2: =IFERROR((R2*L2),"")/K1*0.33 -> 7.2663172 | T2: 2 ярус | V2: Сахар | W2: =W1*2.143 -> 175.24978
A3: Торт Фисташка банан | M3: на квадратную форму | R3: =B2*0.008558882352 -> 19.685429 | S3: =IFERROR((R2*L2),"")/K1*0.2 -> 4.4038286 | T3: 3 ярус | V3: Вода | W3: =W2*0.24 -> 42.059947
N4: Шоколада для ганаша | O4: =P4*B2 -> 59.8 | P4: 0.026 | Q4: гр | R4: Масло сливочное 82,5% | S4: =O4/2 -> 29.9 | U4: 0.035555556 | V4: Лимонная кислота | W4: =W2*0.013 -> 2.2782471
B5: 1 ярус | C5: =C8/R2*S1 -> 463.82324 | F5: 1 ярус | G5: =G8/R2*S1 -> 241.79021 | J5: 1 ярус | K5: =K8/R2*S1 -> 279.89333 | N5: 1 ярус | O5: =O8/R2*S1 -> 63.975619 | R5: 1 ярус | S5: =S8/R2*S1 -> 31.987809 | V5: 1 ярус | W5: =W8/R2*S1 -> 0
B6: 2 ярус | C6: =C8/R2*S2 -> 325.66312 | F6: 2 ярус | G6: =G8/R2*S2 -> 169.76759 | J6: 2 ярус | K6: =K8/R2*S2 -> 196.52085 | N6: 2 ярус | O6: =O8/R2*S2 -> 44.919052 | R6: 2 ярус | S6: =S8/R2*S2 -> 22.459526 | V6: 2 ярус | W6: =W8/R2*S1 -> 0
B7: 3 ярус | C7: =C8/R2*S3 -> 197.37159 | F7: 3 ярус | G7: =G8/R2*S3 -> 102.88945 | J7: 3 ярус | K7: =K8/R2*S3 -> 119.10355 | N7: 3 ярус | O7: =O8/R2*S3 -> 27.223668 | R7: 3 ярус | S7: =S8/R2*S3 -> 13.611834 | V7: 3 ярус | W7: =W8/R2*S3 -> 0
A8: 1 | B8: ='1'!A1 -> Фисташкоый бисквит | C8: ='1'!E2 -> 986.42888 | E8: 2 | F8: ='2'!A1 -> Сливочный крем | G8: ='2'!E2 -> 514.22358 | I8: 3 | J8: ='3'!A1 -> Банановый мусс | K8: ='3'!E2 -> 595.25881 | M8: 4 | N8: ='4'!A1 -> Изоляционный крем | O8: ='4'!E2 -> 136.05916 | Q8: 5 | R8: ='5'!A1 -> Пропитка | S8: ='5'!E2 -> 68.029578 | U8: 6 | V8: ='6'!A1 -> Составляющая | W8: ='6'!E2 -> 0
A9: № | B9: ='1'!G3 -> продукт | C9: ='1'!E3 -> Грамм | E9: № | F9: продукт | G9: Грамм | I9: № | J9: продукт | K9: Грамм | M9: № | N9: продукт | O9: Грамм | Q9: № | R9: продукт | S9: Грамм | U9: № | V9: продукт | W9: Грамм
A10: 1 | B10: ='1'!G4 -> Желток (17 г от 1 яйца) | C10: ='1'!E4 -> 353.15355 | E10: 1 | F10: ='2'!G4 -> Сливки 33 – 35% | G10: ='2'!E4 -> 211.09178 | I10: 1 | J10: ='3'!G4 -> Сливки 33 – 35% | K10: ='3'!E4 -> 211.09178 | M10: 1 | N10: ='4'!G4 -> Молоко сгущенное(380 гр) | O10: ='4'!E4 -> 68.029578 | Q10: 1 | R10: ='5'!G4 -> Кипяток | S10: ='5'!E4 -> 51.022184 | U10: 1 | V10: ='6'!G4 -> 0 | W10: ='6'!E4 -> 0
A11: 2 | B11: ='1'!G5 -> Сахар песок | C11: ='1'!E5 -> 170.07395 | E11: 2 | F11: ='2'!G5 -> Творожный сыр | G11: ='2'!E5 -> 211.09178 | I11: 2 | J11: ='3'!G5 -> Молоко сгущенное(380 гр) | K11: ='3'!E5 -> 127.05524 | M11: 2 | N11: ='4'!G5 -> Масло сливочное 82,5% | O11: ='4'!E5 -> 51.022184 | Q11: 2 | R11: ='5'!G5 -> Молоко сгущенное(380 гр) | S11: ='5'!E5 -> 13.005655 | U11: 2 | V11: ='6'!G5 -> 0 | W11: ='6'!E5 -> 0
A12: 3 | B12: ='1'!G6 -> Масло подсолнечное | C12: ='1'!E6 -> 85.036973 | E12: 3 | F12: ='2'!G6 -> Молоко сгущенное(380 гр) | G12: ='2'!E6 -> 84.036538 | I12: 3 | J12: ='3'!G6 -> Банан кг (120-150гр) | K12: ='3'!E6 -> 245.10657 | M12: 3 | N12: ='4'!G6 -> Шарики рисовые в глазури | O12: ='4'!E6 -> 17.007395 | Q12: 3 | R12: ='5'!G6 -> Паста дес. фисташка | S12: ='5'!E6 -> 4.0017399 | U12: 3 | V12: ='6'!G6 -> 0 | W12: ='6'!E6 -> 0
A13: 4 | B13: ='1'!G7 -> Мука пшеничная | C13: ='1'!E7 -> 325.14137 | E13: 4 | F13: ='2'!G7 -> Ванильный сахар | G13: ='2'!E7 -> 8.0034798 | I13: 4 | J13: ='3'!G7 -> Желатин | K13: ='3'!E7 -> 8.0034798 | M13: 4 | N13: ='4'!G7 -> 0 | O13: ='4'!E7 -> 0 | Q13: 4 | R13: ='5'!G7 -> 0 | S13: ='5'!E7 -> 0 | U13: 4 | V13: ='6'!G7 -> 0 | W13: ='6'!E7 -> 0
A14: 5 | B14: ='1'!G8 -> Паста дес. фисташка | C14: ='1'!E8 -> 35.015224 | E14: 5 | F14: ='2'!G8 -> 0 | G14: ='2'!E8 -> 0 | I14: 5 | J14: ='3'!G8 -> Паста дес. банан | K14: ='3'!E8 -> 4.0017399 | M14: 5 | N14: ='4'!G8 -> 0 | O14: ='4'!E8 -> 0 | Q14: 5 | R14: ='5'!G8 -> 0 | S14: ='5'!E8 -> 0 | U14: 5 | V14: ='6'!G8 -> 0 | W14: ='6'!E8 -> 0
A15: 6 | B15: ='1'!G9 -> Кипяток | C15: ='1'!E9 -> 85.036973 | E15: 6 | F15: ='2'!G9 -> 0 | G15: ='2'!E9 -> 0 | I15: 6 | J15: ='3'!G9 -> 0 | K15: ='3'!E9 -> 0 | M15: 6 | N15: ='4'!G9 -> 0 | O15: ='4'!E9 -> 0 | Q15: 6 | R15: ='5'!G9 -> 0 | S15: ='5'!E9 -> 0 | U15: 6 | V15: ='6'!G9 -> 0 | W15: ='6'!E9 -> 0
A16: 7 | B16: ='1'!G10 -> Разрыхлитель | C16: ='1'!E10 -> 14.00609 | E16: 7 | F16: ='2'!G10 -> 0 | G16: ='2'!E10 -> 0 | I16: 7 | J16: ='3'!G10 -> 0 | K16: ='3'!E10 -> 0 | M16: 7 | N16: ='4'!G10 -> 0 | O16: ='4'!E10 -> 0 | Q16: 7 | R16: ='5'!G10 -> 0 | S16: ='5'!E10 -> 0 | U16: 7 | V16: ='6'!G10 -> 0 | W16: ='6'!E10 -> 0
A17: 8 | B17: ='1'!G11 -> Лимонная кислота | C17: ='1'!E11 -> 2.0008699 | E17: 8 | F17: ='2'!G11 -> 0 | G17: ='2'!E11 -> 0 | I17: 8 | J17: ='3'!G11 -> 0 | K17: ='3'!E11 -> 0 | M17: 8 | N17: ='4'!G11 -> 0 | O17: ='4'!E11 -> 0 | Q17: 8 | R17: ='5'!G11 -> 0 | S17: ='5'!E11 -> 0 | U17: 8 | V17: ='6'!G11 -> 0 | W17: ='6'!E11 -> 0
A18: 9 | B18: ='1'!G12 -> Соль | C18: ='1'!E12 -> 2.0008699 | E18: 9 | F18: ='2'!G12 -> 0 | G18: ='2'!E12 -> 0 | I18: 9 | J18: ='3'!G12 -> 0 | K18: ='3'!E12 -> 0 | M18: 9 | N18: ='4'!G12 -> 0 | O18: ='4'!E12 -> 0 | Q18: 9 | R18: ='5'!G12 -> 0 | S18: ='5'!E12 -> 0 | U18: 9 | V18: ='6'!G12 -> 0 | W18: ='6'!E12 -> 0
A19: 10 | B19: ='1'!G13 -> 0 | C19: ='1'!E13 -> 0 | E19: 10 | F19: ='2'!G13 -> 0 | G19: ='2'!E13 -> 0 | I19: 10 | J19: ='3'!G13 -> 0 | K19: ='3'!E13 -> 0 | M19: 10 | N19: ='4'!G13 -> 0 | O19: ='4'!E13 -> 0 | Q19: 10 | R19: ='5'!G13 -> 0 | S19: ='5'!E13 -> 0 | U19: 10 | V19: ='6'!G13 -> 0 | W19: ='6'!E13 -> 0
A20: 11 | B20: ='1'!G14 -> 0 | C20: ='1'!E14 -> 0 | E20: 11 | F20: ='2'!G14 -> 0 | G20: ='2'!E14 -> 0 | I20: 11 | J20: ='3'!G14 -> 0 | K20: ='3'!E14 -> 0 | M20: 11 | N20: ='4'!G14 -> 0 | O20: ='4'!E14 -> 0 | Q20: 11 | R20: ='5'!G14 -> 0 | S20: ='5'!E14 -> 0 | U20: 11 | V20: ='6'!G14 -> 0 | W20: ='6'!E14 -> 0
A21: 12 | B21: ='1'!G15 -> 0 | C21: ='1'!E15 -> 0 | E21: 12 | F21: ='2'!G15 -> 0 | G21: ='2'!E15 -> 0 | I21: 12 | J21: ='3'!G15 -> 0 | K21: ='3'!E15 -> 0 | M21: 12 | N21: ='4'!G15 -> 0 | O21: ='4'!E15 -> 0 | Q21: 12 | R21: ='5'!G15 -> 0 | S21: ='5'!E15 -> 0 | U21: 12 | V21: ='6'!G15 -> 0 | W21: ='6'!E15 -> 0
... A23: 14 | B23: ='1'!G17 -> 0 | C23: ='1'!E17 -> 0 | E23: 14 | F23: ='2'!G17 -> 0 | G23: ='2'!E17 -> 0 | I23: 14 | J23: ='3'!G17 -> 0 | K23: ='3'!E17 -> 0 | M23: 14 | N23: ='4'!G17 -> 0 | O23: ='4'!E17 -> 0 | Q23: 14 | R23: ='5'!G17 -> 0 | S23: ='5'!E17 -> 0 | U23: 14 | V23: ='6'!G17 -> 0 | W23: ='6'!E17 -> 0
A24: ='1'!A2 -> Технология приготовления: | E24: ='2'!A2 -> Технология приготовления: | I24: ='3'!A2 -> Технология приготовления: | M24: ='4'!A2 -> Технология приготовления: | Q24: ='5'!A2 -> Технология приготовления: | U24: ='6'!A2 -> Технология приготовления:
A25: ='1'!A3 -> Просеять муку, добавить соль, разрыхлитель, лимонку. Все перемешать В чаше миксера соединить сахар и яйца. Взбивать до белой пены не менее 10 минут. Тем временем вскипятить воду. Соединить пасту с маслом. Когда яичная смесь взобьется добавить пасту с маслом, перемешать. Добавить кипяток и муку. Аккуратно перемешать. Для обычного торта делим на 2 и разливаем по формам. Выпекаем 180 градусов. Без конвекции до сухой лучины. Примерно 40 минут. | E25: ='2'!A3 -> Перед взбиванием дежу миксера желательно охладить 10 минут в холодильник. Все соединить, взбить до устойчивых пиков. | I25: ='3'!A3 -> Бананы очистить, порезать на кусочки, проварить в микроволновке до мягкого состояния | M25: ='4'!A3 -> Масло взбить до бела, частями добавлять сгущенку, до полного соединения, немного остудить добавить шарики. Все хорошо промешать, что бы шарики были произолированы и не размокли от других кремов. | Q25: ='5'!A3 -> Сгущенку и пасту размешать с водой. | U25: ='6'!A3 -> 0
A26: Сборка: Разрезать коржи, делить вес крема на столько, сколько прослоек у вас будет. если бисквитов получится 4, то соответственно прослоек крема 3 . Сборка: Бисквит- пропитать– сливочный крем промазать низ , потолще бортики по краям и середина кольцо – между крема заполнить банановым муссом-бисквит– пропитать– сливочный крем промазать низ, потолще бортики по краям и середина кольцо– между бортиков заполнитьбанановым муссом - и т.д. 2 верхних слоя в мусс по бортикам, так же по бортикам из. крем с шариками - бисквит. Даем ночь пропитаться, торт ганашим
B27: Расчет Себестоимости торта
B28: ='Расчет с_стоим'!B2 -> Продукты | C28: ='Расчет с_стоим'!E3 -> 0 | F28: ='Расчет с_стоим'!G2 -> Инвентарь, упаковка, дополнения к заказу | G28: ='Расчет с_стоим'!J3 -> 205.3 | J28: ='Расчет с_стоим'!L3 -> Доставка | K28: ='Расчет с_стоим'!M3 -> 0 | O28: Всего | R28: =C28+G28+K28 -> 205.3

Sheet Для закупа
B1: Продукт | C1: грамм | D1: Закуп?
A2: Покрытие | B2: =Технология!N4 -> Шоколада для ганаша | C2: =Технология!O4 -> 59.8
B3: =Технология!R4 -> Масло сливочное 82,5% | C3: =Технология!S4 -> 29.9
B4: =Технология!V1 -> Белок на БЗК гр | C4: =Технология!W1 -> 81.777778
B5: =Технология!V2 -> Сахар | C5: =Технология!W2 -> 175.24978
B6: =Технология!V3 -> Вода | C6: =Технология!W3 -> 42.059947
B7: =Технология!V4 -> Лимонная кислота | C7: =Технология!W4 -> 2.2782471
A8: Инвентарь в штуках | B8: ='Расчет с_стоим'!G4 -> Кондитерский мешок | C8: ='Расчет с_стоим'!H4 -> 0
B9: ='Расчет с_стоим'!G5 -> Коробка для торта | C9: ='Расчет с_стоим'!H5 -> 0
B10: ='Расчет с_стоим'!G6 -> Пакет фасовочный 12*14 | C10: ='Расчет с_стоим'!H6 -> 0
B11: ='Расчет с_стоим'!G7 -> Подложка 2 толщ 30*30 см | C11: ='Расчет с_стоим'!H7 -> 0
B12: ='Расчет с_стоим'!G8 -> Шпажки маленькие | C12: ='Расчет с_стоим'!H8 -> 0
B13: ='Расчет с_стоим'!G9 -> Электричество | C13: ='Расчет с_стоим'!H9 -> 10
B14: ='Расчет с_стоим'!G10 -> Зефирные фигурки | C14: ='Расчет с_стоим'!H10 -> 0
B15: ='Расчет с_стоим'!G11 -> Палочки для мороженного | C15: ='Расчет с_стоим'!H11 -> 0
B16: ='Расчет с_стоим'!G12 -> Упаковочная бумага цвет | C16: ='Расчет с_стоим'!H12 -> 50
B17: ='Расчет с_стоим'!G13 -> 0 | C17: ='Расчет с_стоим'!H13 -> 0
B18: ='Расчет с_стоим'!G14 -> 0 | C18: ='Расчет с_стоим'!H14 -> 0
B19: ='Расчет с_стоим'!G15 -> 0 | C19: ='Расчет с_стоим'!H15 -> 0
B20: ='Расчет с_стоим'!G16 -> 0 | C20: ='Расчет с_стоим'!H16 -> 0
... B29: ='Расчет с_стоим'!G25 -> 0 | C29: ='Расчет с_стоим'!H25 -> 0
A30: 1 | B30: =Технология!B10 -> Желток (17 г от 1 яйца) | C30: =Технология!C10 -> 353.15355
A31: 2 | B31: =Технология!B11 -> Сахар песок | C31: =Технология!C11 -> 170.07395
A32: 3 | B32: =Технология!B12 -> Масло подсолнечное | C32: =Технология!C12 -> 85.036973
A33: 4 | B33: =Технология!B13 -> Мука пшеничная | C33: =Технология!C13 -> 325.14137
A34: 5 | B34: =Технология!B14 -> Паста дес. фисташка | C34: =Технология!C14 -> 35.015224
A35: 6 | B35: =Технология!B15 -> Кипяток | C35: =Технология!C15 -> 85.036973
A36: 7 | B36: =Технология!B16 -> Разрыхлитель | C36: =Технология!C16 -> 14.00609
A37: 8 | B37: =Технология!B17 -> Лимонная кислота | C37: =Технология!C17 -> 2.0008699
A38: 9 | B38: =Технология!B18 -> Соль | C38: =Технология!C18 -> 2.0008699
A39: 10 | B39: =Технология!B19 -> 0 | C39: =Технология!C19 -> 0
A40: 11 | B40: =Технология!B20 -> 0 | C40: =Технология!C20 -> 0
A41: 12 | B41: =Технология!B21 -> 0 | C41: =Технология!C21 -> 0
... A43: 14 | B43: =Технология!B23 -> 0 | C43: =Технология!C23 -> 0
A44: 1 | B44: =Технология!F10 -> Сливки 33 – 35% | C44: =Технология!G10 -> 211.09178
A45: 2 | B45: =Технология!F11 -> Творожный сыр | C45: =Технология!G11 -> 211.09178
A46: 3 | B46: =Технология!F12 -> Молоко сгущенное(380 гр) | C46: =Технология!G12 -> 84.036538
A47: 4 | B47: =Технология!F13 -> Ванильный сахар | C47: =Технология!G13 -> 8.0034798
A48: 5 | B48: =Технология!F14 -> 0 | C48: =Технология!G14 -> 0
A49: 6 | B49: =Технология!F15 -> 0 | C49: =Технология!G15 -> 0
...

Sheet Расчет с_стоим
B1: Всего | C1: =E3+J3+M3 -> 205.3 | N1: Испарения при выпекании | P1: =SUM(P2:P3) -> 186.98552 | Q1: гр
B2: Продукты | C2: грамм | D2: Цена за | E2: Стоимость | G2: Инвентарь, упаковка, дополнения к заказу | H2: шт | I2: Цена за | J2: Стоимость | N2: Указать общий объем бисквита | O2: =Технология!C8 -> 986.42888 | P2: =O2*14.691943/100 -> 144.92557
B3: Итого | C3: =SUM(C4:C93)-P1 -> 2589.1172 | D3: грамм | E3: =SUM(E4:E93) -> 0 | G3: Итого | I3: единицу | J3: =SUM(J4:J93) -> 205.3 | L3: Доставка | M3: 0 | N3: Меренга | P3: =C8 -> 42.059947
A4: Покрытие | B4: =Технология!N4 -> Шоколада для ганаша | C4: =Технология!O4 -> 59.8 | E4: =C4*D4 -> 0 | G4: Кондитерский мешок | H4: 0 | I4: 1.5 | J4: =H4*I4 -> 0
B5: =Технология!R4 -> Масло сливочное 82,5% | C5: =Технология!S4 -> 29.9 | E5: =C5*D5 -> 0 | G5: Коробка для торта | I5: 137 | J5: =H5*I5 -> 0
B6: =Технология!V1 -> Белок на БЗК гр | C6: =Технология!W1 -> 81.777778 | E6: =C6*D6 -> 0 | G6: Пакет фасовочный 12*14 | I6: 2.66 | J6: =H6*I6 -> 0
B7: =Технология!V2 -> Сахар | C7: =Технология!W2 -> 175.24978 | E7: =C7*D7 -> 0 | G7: Подложка 2 толщ 30*30 см | H7: 0 | I7: 0.02134949 | J7: =H7*I7 -> 0
B8: =Технология!V3 -> Вода | C8: =Технология!W3 -> 42.059947 | E8: =C8*D8 -> 0 | G8: Шпажки маленькие | I8: 0.6 | J8: =H8*I8 -> 0
B9: =Технология!V4 -> Лимонная кислота | C9: =Технология!W4 -> 2.2782471 | E9: =C9*D9 -> 0 | G9: Электричество | H9: 10 | I9: 5.13 | J9: =H9*I9 -> 51.3
A10: 1 | B10: =Технология!B10 -> Желток (17 г от 1 яйца) | C10: =Технология!C10 -> 353.15355 | E10: =C10*D10 -> 0 | G10: Зефирные фигурки | I10: 70 | J10: =H10*I10 -> 0
A11: 2 | B11: =Технология!B11 -> Сахар песок | C11: =Технология!C11 -> 170.07395 | E11: =C11*D11 -> 0 | G11: Палочки для мороженного | I11: 1.32 | J11: =H11*I11 -> 0
A12: 3 | B12: =Технология!B12 -> Масло подсолнечное | C12: =Технология!C12 -> 85.036973 | E12: =C12*D12 -> 0 | G12: Упаковочная бумага цвет | H12: 50 | I12: 3.08 | J12: =H12*I12 -> 154
A13: 4 | B13: =Технология!B13 -> Мука пшеничная | C13: =Технология!C13 -> 325.14137 | E13: =C13*D13 -> 0 | J13: =H13*I13 -> 0
A14: 5 | B14: =Технология!B14 -> Паста дес. фисташка | C14: =Технология!C14 -> 35.015224 | E14: =C14*D14 -> 0 | J14: =H14*I14 -> 0
A15: 6 | B15: =Технология!B15 -> Кипяток | C15: =Технология!C15 -> 85.036973 | E15: =C15*D15 -> 0 | J15: =H15*I15 -> 0
A16: 7 | B16: =Технология!B16 -> Разрыхлитель | C16: =Технология!C16 -> 14.00609 | E16: =C16*D16 -> 0 | J16: =H16*I16 -> 0
A17: 8 | B17: =Технология!B17 -> Лимонная кислота | C17: =Технология!C17 -> 2.0008699 | E17: =C17*D17 -> 0 | J17: =H17*I17 -> 0
A18: 9 | B18: =Технология!B18 -> Соль | C18: =Технология!C18 -> 2.0008699 | E18: =C18*D18 -> 0 | J18: =H18*I18 -> 0
A19: 10 | B19: =Технология!B19 -> 0 | C19: =Технология!C19 -> 0 | E19: =C19*D19 -> 0 | J19: =H19*I19 -> 0
A20: 11 | B20: =Технология!B20 -> 0 | C20: =Технология!C20 -> 0 | E20: =C20*D20 -> 0 | J20: =H20*I20 -> 0
A21: 12 | B21: =Технология!B21 -> 0 | C21: =Технология!C21 -> 0 | E21: =C21*D21 -> 0 | J21: =H21*I21 -> 0
A22: 13 | B22: =Технология!B22 -> 0 | C22: =Технология!C22 -> 0 | E22: =C22*D22 -> 0 | J22: =H22*I22 -> 0
A23: 14 | B23: =Технология!B23 -> 0 | C23: =Технология!C23 -> 0 | E23: =C23*D23 -> 0 | J23: =H23*I23 -> 0
A24: 1 | B24: =Технология!F10 -> Сливки 33 – 35% | C24: =Технология!G10 -> 211.09178 | E24: =C24*D24 -> 0 | J24: =H24*I24 -> 0
A25: 2 | B25: =Технология!F11 -> Творожный сыр | C25: =Технология!G11 -> 211.09178 | E25: =C25*D25 -> 0 | J25: =H25*I25 -> 0
A26: 3 | B26: =Технология!F12 -> Молоко сгущенное(380 гр) | C26: =Технология!G12 -> 84.036538 | E26: =C26*D26 -> 0
A27: 4 | B27: =Технология!F13 -> Ванильный сахар | C27: =Технология!G13 -> 8.0034798 | E27: =C27*D27 -> 0
A28: 5 | B28: =Технология!F14 -> 0 | C28: =Технология!G14 -> 0 | E28: =C28*D28 -> 0
A29: 6 | B29: =Технология!F15 -> 0 | C29: =Технология!G15 -> 0 | E29: =C29*D29 -> 0
A30: 7 | B30: =Технология!F16 -> 0 | C30: =Технология!G16 -> 0 | E30: =C30*D30 -> 0
A31: 8 | B31: =Технология!F17 -> 0 | C31: =Технология!G17 -> 0 | E31: =C31*D31 -> 0
A32: 9 | B32: =Технология!F18 -> 0 | C32: =Технология!G18 -> 0 | E32: =C32*D32 -> 0
A33: 10 | B33: =Технология!F19 -> 0 | C33: =Технология!G19 -> 0 | E33: =C33*D33 -> 0
A34: 11 | B34: =Технология!F20 -> 0 | C34: =Технология!G20 -> 0 | E34: =C34*D34 -> 0
A35: 12 | B35: =Технология!F21 -> 0 | C35: =Технология!G21 -> 0 | E35: =C35*D35 -> 0
A36: 13 | B36: =Технология!F22 -> 0 | C36: =Технология!G22 -> 0 | E36: =C36*D36 -> 0
A37: 14 | B37: =Технология!F23 -> 0 | C37: =Технология!G23 -> 0 | E37: =C37*D37 -> 0
A38: 1 | B38: =Технология!J10 -> Сливки 33 – 35% | C38: =Технология!K10 -> 211.09178 | E38: =C38*D38 -> 0
A39: 2 | B39: =Технология!J11 -> Молоко сгущенное(380 гр) | C39: =Технология!K11 -> 127.05524 | E39: =C39*D39 -> 0
A40: 3 | B40: =Технология!J12 -> Банан кг (120-150гр) | C40: =Технология!K12 -> 245.10657 | E40: =C40*D40 -> 0
...

Sheet 1
A1: Фисташкоый бисквит
A2: Технология приготовления: | E2: =SUM(E4:E17)-E9 -> 986.42888 | F2: =SUM(F4:F17)-F9 -> 986 | G2: вес массы в гр.
A3: Просеять муку, добавить соль, разрыхлитель, лимонку. Все перемешать В чаше миксера соединить сахар и яйца. Взбивать до белой пены не менее 10 минут. Тем временем вскипятить воду. Соединить пасту с маслом. Когда яичная смесь взобьется добавить пасту с маслом, перемешать. Добавить кипяток и муку. Аккуратно перемешать. Для обычного торта делим на 2 и разливаем по формам. Выпекаем 180 градусов. Без конвекции до сухой лучины. Примерно 40 минут. | E3: Грамм | F3: Грамм | G3: продукт
E4: =F4*Технология!I1 -> 353.15355 | F4: 353 | G4: Желток (17 г от 1 яйца)
E5: =F5*Технология!I1 -> 170.07395 | F5: 170 | G5: Сахар песок
E6: =F6*Технология!I1 -> 85.036973 | F6: 85 | G6: Масло подсолнечное
E7: =F7*Технология!I1 -> 325.14137 | F7: 325 | G7: Мука пшеничная
E8: =F8*Технология!I1 -> 35.015224 | F8: 35 | G8: Паста дес. фисташка
E9: =F9*Технология!I1 -> 85.036973 | F9: 85 | G9: Кипяток
E10: =F10*Технология!I1 -> 14.00609 | F10: 14 | G10: Разрыхлитель
E11: =F11*Технология!I1 -> 2.0008699 | F11: 2 | G11: Лимонная кислота
E12: =F12*Технология!I1 -> 2.0008699 | F12: 2 | G12: Соль
E13: =F13*Технология!I1 -> 0
E14: =F14*Технология!I1 -> 0
E15: =F15*Технология!I1 -> 0
E16: =F16*Технология!I1 -> 0
E17: =F17*Технология!I1 -> 0

Sheet 2
A1: Сливочный крем
A2: Технология приготовления: | E2: =SUM(E4:E17)-E9 -> 514.22358 | F2: =SUM(F4:F17)-F9 -> 514 | G2: вес массы в гр.
A3: Перед взбиванием дежу миксера желательно охладить 10 минут в холодильник. Все соединить, взбить до устойчивых пиков. | E3: Грамм | F3: Грамм | G3: продукт
E4: =F4*Технология!I1 -> 211.09178 | F4: 211 | G4: Сливки 33 – 35%
E5: =F5*Технология!I1 -> 211.09178 | F5: 211 | G5: Творожный сыр
E6: =F6*Технология!I1 -> 84.036538 | F6: 84 | G6: Молоко сгущенное(380 гр)
E7: =F7*Технология!I1 -> 8.0034798 | F7: 8 | G7: Ванильный сахар
E8: =F8*Технология!I1 -> 0
E9: =F9*Технология!I1 -> 0
E10: =F10*Технология!I1 -> 0
E11: =F11*Технология!I1 -> 0
E12: =F12*Технология!I1 -> 0
E13: =F13*Технология!I1 -> 0
E14: =F14*Технология!I1 -> 0
E15: =F15*Технология!I1 -> 0
E16: =F16*Технология!I1 -> 0
E17: =F17*Технология!I1 -> 0

Sheet 3
A1: Банановый мусс
A2: Технология приготовления: | E2: =SUM(E4:E17)-E9 -> 595.25881 | F2: =SUM(F4:F17)-F9 -> 595 | G2: вес массы в гр.
A3: Бананы очистить, порезать на кусочки, проварить в микроволновке до мягкого состояния | E3: Грамм | F3: Грамм | G3: продукт
E4: =F4*Технология!I1 -> 211.09178 | F4: 211 | G4: Сливки 33 – 35%
E5: =F5*Технология!I1 -> 127.05524 | F5: 127 | G5: Молоко сгущенное(380 гр)
E6: =F6*Технология!I1 -> 245.10657 | F6: 245 | G6: Банан кг (120-150гр)
E7: =F7*Технология!I1 -> 8.0034798 | F7: 8 | G7: Желатин
E8: =F8*Технология!I1 -> 4.0017399 | F8: 4 | G8: Паста дес. банан
E9: =F9*Технология!I1 -> 0
E10: =F10*Технология!I1 -> 0
E11: =F11*Технология!I1 -> 0
E12: =F12*Технология!I1 -> 0
E13: =F13*Технология!I1 -> 0
E14: =F14*Технология!I1 -> 0
E15: =F15*Технология!I1 -> 0
E16: =F16*Технология!I1 -> 0
E17: =F17*Технология!I1 -> 0

Sheet 4
A1: Изоляционный крем
A2: Технология приготовления: | E2: =SUM(E4:E17)-E9 -> 136.05916 | F2: =SUM(F4:F17)-F9 -> 136 | G2: вес массы в гр.
A3: Масло взбить до бела, частями добавлять сгущенку, до полного соединения, немного остудить добавить шарики. Все хорошо промешать, что бы шарики были произолированы и не размокли от других кремов. | E3: Грамм | F3: Грамм | G3: продукт
E4: =F4*Технология!I1 -> 68.029578 | F4: 68 | G4: Молоко сгущенное(380 гр)
E5: =F5*Технология!I1 -> 51.022184 | F5: 51 | G5: Масло сливочное 82,5%
E6: =F6*Технология!I1 -> 17.007395 | F6: 17 | G6: Шарики рисовые в глазури
E7: =F7*Технология!I1 -> 0
E8: =F8*Технология!I1 -> 0
E9: =F9*Технология!I1 -> 0
E10: =F10*Технология!I1 -> 0
E11: =F11*Технология!I1 -> 0
E12: =F12*Технология!I1 -> 0
E13: =F13*Технология!I1 -> 0
E14: =F14*Технология!I1 -> 0
E15: =F15*Технология!I1 -> 0
E16: =F16*Технология!I1 -> 0
E17: =F17*Технология!I1 -> 0

Sheet 5
A1: Пропитка
A2: Технология приготовления: | E2: =SUM(E4:E17)-E9 -> 68.029578 | F2: =SUM(F4:F17)-F9 -> 68 | G2: вес массы в гр.
A3: Сгущенку и пасту размешать с водой. | E3: Грамм | F3: Грамм | G3: продукт
E4: =F4*Технология!I1 -> 51.022184 | F4: 51 | G4: Кипяток
E5: =F5*Технология!I1 -> 13.005655 | F5: 13 | G5: Молоко сгущенное(380 гр)
E6: =F6*Технология!I1 -> 4.0017399 | F6: 4 | G6: Паста дес. фисташка
E7: =F7*Технология!I1 -> 0
E8: =F8*Технология!I1 -> 0
E9: =F9*Технология!I1 -> 0
E10: =F10*Технология!I1 -> 0
E11: =F11*Технология!I1 -> 0
E12: =F12*Технология!I1 -> 0
E13: =F13*Технология!I1 -> 0
E14: =F14*Технология!I1 -> 0
E15: =F15*Технология!I1 -> 0
E16: =F16*Технология!I1 -> 0
E17: =F17*Технология!I1 -> 0

Sheet 6
A1: Составляющая
A2: Технология приготовления: | E2: =SUM(E4:E17)-E9 -> 0 | F2: =SUM(F4:F17)-F9 -> 0 | G2: вес массы в гр.
E3: Грамм | F3: Грамм | G3: продукт
E4: =F4*Технология!I1 -> 0
E5: =F5*Технология!I1 -> 0
E6: =F6*Технология!I1 -> 0
E7: =F7*Технология!I1 -> 0
E8: =F8*Технология!I1 -> 0
E9: =F9*Технология!I1 -> 0
E10: =F10*Технология!I1 -> 0
E11: =F11*Технология!I1 -> 0
E12: =F12*Технология!I1 -> 0
E13: =F13*Технология!I1 -> 0
E14: =F14*Технология!I1 -> 0
E15: =F15*Технология!I1 -> 0
E16: =F16*Технология!I1 -> 0
E17: =F17*Технология!I1 -> 0

Sheet С стоимость
A1: =[1]Лист1!A2 -> Бобы тонка | B1: =[1]Лист1!D2 -> 1000
A2: =[1]Лист1!A3 -> Агар-Агар | B2: =[1]Лист1!D3 -> 1000
A3: =[1]Лист1!A4 -> Арахис | B3: =[1]Лист1!D4 -> 200
A4: =[1]Лист1!A5 -> Ваниль (стручок) | B4: =[1]Лист1!D5 -> 1000
A5: =[1]Лист1!A6 -> Ванильный йогурт | B5: =[1]Лист1!D6 -> 1000
A6: =[1]Лист1!A7 -> Ванильный сахар | B6: =[1]Лист1!D7 -> 8
A7: =[1]Лист1!A8 -> Ванильный экстракт | B7: =[1]Лист1!D8 -> 1000
A8: =[1]Лист1!A9 -> Вафли трубочки | B8: =[1]Лист1!D9 -> 400
A9: =[1]Лист1!A10 -> Вода | B9: =[1]Лист1!D10 -> 1000
A10: =[1]Лист1!A11 -> Глюкоза | B10: =[1]Лист1!D11 -> 300
A11: =[1]Лист1!A12 -> Груша очищенная | B11: =[1]Лист1!D12 -> 1000
A12: =[1]Лист1!A13 -> Желатин | B12: =[1]Лист1!D13 -> 50
... A150: =[1]Лист1!A151 -> 0 | B150: =[1]Лист1!D151 -> 0
